<robot name="MockGripper" xmlns:xacro="http://www.ros.org/wiki/xacro">

  <xacro:include filename="$(find MockGripper_description)/urdf/materials.xacro" />
  <xacro:include filename="$(find MockGripper_description)/urdf/MockGripper.trans" />
  <xacro:include filename="$(find MockGripper_description)/urdf/MockGripper.gazebo" />
  <xacro:include filename="$(find cv_ur5_project)/urdf/ur5.urdf.xacro" />


  <gazebo>
    <plugin name="gazebo_ros_control" filename="libgazebo_ros_control.so">
      <robotNamespace>/MockGripper</robotNamespace>
    </plugin>
  </gazebo>

  <link name="gripper_base_link">
    <inertial>
      <origin xyz="8.270000509100169e-15 1.1655312332230407e-15 0.022197609852077728" rpy="0 0 0"/>
      <mass value="0.27660129636987535"/>
      <inertia ixx="9.3e-05" iyy="0.000536" izz="0.000561" ixy="0.0" iyz="-0.0" ixz="-0.0"/>
    </inertial>
    <visual>
      <origin xyz="0 0 0" rpy="0 0 0"/>
      <geometry>
        <mesh filename="package://MockGripper_description/meshes/base_link.stl" scale="0.001 0.001 0.001"/>
      </geometry>
      <material name="gray"/>
    </visual>
    <collision>
      <origin xyz="0 0 0" rpy="0 0 0"/>
      <geometry>
        <mesh filename="package://MockGripper_description/meshes/base_link.stl" scale="0.001 0.001 0.001"/>
      </geometry>
    </collision>
  </link>

  <link name="left_finger_1">
    <inertial>
      <origin xyz="0.09050000000001658 0.019000000000002334 0.05079999999999999" rpy="0 0 0"/>
      <mass value="0.07816629528000005"/>
      <inertia ixx="7.7e-05" iyy="7e-05" izz="1.2e-05" ixy="0.0" iyz="-0.0" ixz="0.0"/>
    </inertial>
    <visual>
      <origin xyz="-0.0 0.01905 -0.0381" rpy="0 0 0"/>
      <geometry>
        <mesh filename="package://MockGripper_description/meshes/left_finger_1.stl" scale="0.001 0.001 0.001"/>
      </geometry>
      <material name="off_white"/>
    </visual>
    <collision>
      <origin xyz="-0.0 0.01905 -0.0381" rpy="0 0 0"/>
      <geometry>
        <mesh filename="package://MockGripper_description/meshes/left_finger_1.stl" scale="0.001 0.001 0.001"/>
      </geometry>
    </collision>
  </link>

  <link name="right_finger_1">
    <inertial>
      <origin xyz="-0.09049999999998343 0.019000000000002258 0.050800000000000005" rpy="0 0 0"/>
      <mass value="0.07816629527986343"/>
      <inertia ixx="7.7e-05" iyy="7e-05" izz="1.2e-05" ixy="0.0" iyz="0.0" ixz="-0.0"/>
    </inertial>
    <visual>
      <origin xyz="-0.0 0.01905 -0.0381" rpy="0 0 0"/>
      <geometry>
        <mesh filename="package://MockGripper_description/meshes/right_finger_1.stl" scale="0.001 0.001 0.001"/>
      </geometry>
      <material name="off_white"/>
    </visual>
    <collision>
      <origin xyz="-0.0 0.01905 -0.0381" rpy="0 0 0"/>
      <geometry>
        <mesh filename="package://MockGripper_description/meshes/right_finger_1.stl" scale="0.001 0.001 0.001"/>
      </geometry>
    </collision>
  </link>

  <joint name="gripper_base_joint" type="fixed">
    <parent link="\ee_link" />
    <child link = "gripper_base_link" />
    <origin xyz="0.0 0.0 0.0" rpy="0.0 ${pi/2.0} 0.0" />
  </joint>

  <joint name="Slider1" type="prismatic">
    <origin xyz="0.0 -0.01905 0.0381" rpy="0 0 0"/>
    <parent link="gripper_base_link"/>
    <child link="left_finger_1"/>
    <axis xyz="1.0 0.0 0.0"/>
    <limit upper="0.001" lower="-0.075" effort="100" velocity="100"/>
  </joint>

  <joint name="Slider2" type="prismatic">
    <origin xyz="0.0 -0.01905 0.0381" rpy="0 0 0"/>
    <parent link="gripper_base_link"/>
    <child link="right_finger_1"/>
    <axis xyz="1.0 0.0 0.0"/>
    <limit upper="0.075" lower="0.0" effort="100" velocity="100"/>
  </joint>

</robot>
